[2022-07-05 09:44:38,597] {taskinstance.py:1159} INFO - Dependencies all met for <TaskInstance: sql_branch_dag.create_table manual__2022-07-05T09:44:37.184313+00:00 [queued]>
[2022-07-05 09:44:38,625] {taskinstance.py:1159} INFO - Dependencies all met for <TaskInstance: sql_branch_dag.create_table manual__2022-07-05T09:44:37.184313+00:00 [queued]>
[2022-07-05 09:44:38,626] {taskinstance.py:1356} INFO - 
--------------------------------------------------------------------------------
[2022-07-05 09:44:38,627] {taskinstance.py:1357} INFO - Starting attempt 1 of 1
[2022-07-05 09:44:38,627] {taskinstance.py:1358} INFO - 
--------------------------------------------------------------------------------
[2022-07-05 09:44:38,677] {taskinstance.py:1377} INFO - Executing <Task(PostgresOperator): create_table> on 2022-07-05 09:44:37.184313+00:00
[2022-07-05 09:44:38,689] {standard_task_runner.py:52} INFO - Started process 1048 to run task
[2022-07-05 09:44:38,701] {standard_task_runner.py:79} INFO - Running: ['***', 'tasks', 'run', 'sql_branch_dag', 'create_table', 'manual__2022-07-05T09:44:37.184313+00:00', '--job-id', '131', '--raw', '--subdir', 'DAGS_FOLDER/sql_branch_operator.py', '--cfg-path', '/tmp/tmpqzaxq7n9', '--error-file', '/tmp/tmp0fayb5a9']
[2022-07-05 09:44:38,701] {standard_task_runner.py:80} INFO - Job 131: Subtask create_table
[2022-07-05 09:44:38,855] {task_command.py:370} INFO - Running <TaskInstance: sql_branch_dag.create_table manual__2022-07-05T09:44:37.184313+00:00 [running]> on host dfb99dfc9d64
[2022-07-05 09:44:39,084] {taskinstance.py:1571} INFO - Exporting the following env vars:
AIRFLOW_CTX_DAG_OWNER=***
AIRFLOW_CTX_DAG_ID=sql_branch_dag
AIRFLOW_CTX_TASK_ID=create_table
AIRFLOW_CTX_EXECUTION_DATE=2022-07-05T09:44:37.184313+00:00
AIRFLOW_CTX_TRY_NUMBER=1
AIRFLOW_CTX_DAG_RUN_ID=manual__2022-07-05T09:44:37.184313+00:00
[2022-07-05 09:44:39,138] {taskinstance.py:1889} ERROR - Task failed with exception
Traceback (most recent call last):
  File "/home/airflow/.local/lib/python3.7/site-packages/airflow/providers/postgres/operators/postgres.py", line 92, in execute
    self.hook.run(self.sql, self.autocommit, parameters=self.parameters)
  File "/home/airflow/.local/lib/python3.7/site-packages/airflow/hooks/dbapi.py", line 186, in run
    with closing(self.get_conn()) as conn:
  File "/home/airflow/.local/lib/python3.7/site-packages/airflow/providers/postgres/hooks/postgres.py", line 86, in get_conn
    conn = deepcopy(self.connection or self.get_connection(conn_id))
  File "/home/airflow/.local/lib/python3.7/site-packages/airflow/hooks/base.py", line 67, in get_connection
    conn = Connection.get_connection_from_secrets(conn_id)
  File "/home/airflow/.local/lib/python3.7/site-packages/airflow/models/connection.py", line 430, in get_connection_from_secrets
    raise AirflowNotFoundException(f"The conn_id `{conn_id}` isn't defined")
airflow.exceptions.AirflowNotFoundException: The conn_id `postgres` isn't defined
[2022-07-05 09:44:39,156] {taskinstance.py:1400} INFO - Marking task as FAILED. dag_id=sql_branch_dag, task_id=create_table, execution_date=20220705T094437, start_date=20220705T094438, end_date=20220705T094439
[2022-07-05 09:44:39,182] {standard_task_runner.py:97} ERROR - Failed to execute job 131 for task create_table (The conn_id `postgres` isn't defined; 1048)
[2022-07-05 09:44:39,204] {local_task_job.py:156} INFO - Task exited with return code 1
[2022-07-05 09:44:39,345] {local_task_job.py:273} INFO - 0 downstream tasks scheduled from follow-on schedule check
