[2022-07-04 16:06:51,064] {taskinstance.py:1159} INFO - Dependencies all met for <TaskInstance: first_dag.store_user manual__2022-07-04T16:06:44.457684+00:00 [queued]>
[2022-07-04 16:06:51,074] {taskinstance.py:1159} INFO - Dependencies all met for <TaskInstance: first_dag.store_user manual__2022-07-04T16:06:44.457684+00:00 [queued]>
[2022-07-04 16:06:51,074] {taskinstance.py:1356} INFO - 
--------------------------------------------------------------------------------
[2022-07-04 16:06:51,074] {taskinstance.py:1357} INFO - Starting attempt 1 of 1
[2022-07-04 16:06:51,074] {taskinstance.py:1358} INFO - 
--------------------------------------------------------------------------------
[2022-07-04 16:06:51,089] {taskinstance.py:1377} INFO - Executing <Task(PythonOperator): store_user> on 2022-07-04 16:06:44.457684+00:00
[2022-07-04 16:06:51,094] {standard_task_runner.py:52} INFO - Started process 1076 to run task
[2022-07-04 16:06:51,101] {standard_task_runner.py:79} INFO - Running: ['***', 'tasks', 'run', 'first_dag', 'store_user', 'manual__2022-07-04T16:06:44.457684+00:00', '--job-id', '30', '--raw', '--subdir', 'DAGS_FOLDER/first_dag.py', '--cfg-path', '/tmp/tmpwz0cgdae', '--error-file', '/tmp/tmpo46wgwns']
[2022-07-04 16:06:51,102] {standard_task_runner.py:80} INFO - Job 30: Subtask store_user
[2022-07-04 16:06:51,158] {task_command.py:370} INFO - Running <TaskInstance: first_dag.store_user manual__2022-07-04T16:06:44.457684+00:00 [running]> on host b631230cc7b5
[2022-07-04 16:06:51,233] {taskinstance.py:1571} INFO - Exporting the following env vars:
AIRFLOW_CTX_DAG_OWNER=***
AIRFLOW_CTX_DAG_ID=first_dag
AIRFLOW_CTX_TASK_ID=store_user
AIRFLOW_CTX_EXECUTION_DATE=2022-07-04T16:06:44.457684+00:00
AIRFLOW_CTX_TRY_NUMBER=1
AIRFLOW_CTX_DAG_RUN_ID=manual__2022-07-04T16:06:44.457684+00:00
[2022-07-04 16:06:51,237] {taskinstance.py:1889} ERROR - Task failed with exception
Traceback (most recent call last):
  File "/home/airflow/.local/lib/python3.7/site-packages/airflow/operators/python.py", line 171, in execute
    return_value = self.execute_callable()
  File "/home/airflow/.local/lib/python3.7/site-packages/airflow/operators/python.py", line 189, in execute_callable
    return self.python_callable(*self.op_args, **self.op_kwargs)
  File "/opt/airflow/dags/first_dag.py", line 24, in _store_user
    hook = PostgresHook(postgres_conn_id='postgres')
NameError: name 'PostgresHook' is not defined
[2022-07-04 16:06:51,245] {taskinstance.py:1400} INFO - Marking task as FAILED. dag_id=first_dag, task_id=store_user, execution_date=20220704T160644, start_date=20220704T160651, end_date=20220704T160651
[2022-07-04 16:06:51,256] {standard_task_runner.py:97} ERROR - Failed to execute job 30 for task store_user (name 'PostgresHook' is not defined; 1076)
[2022-07-04 16:06:51,277] {local_task_job.py:156} INFO - Task exited with return code 1
[2022-07-04 16:06:51,310] {local_task_job.py:273} INFO - 0 downstream tasks scheduled from follow-on schedule check
